std::throw_with_nested

   From cppreference.com
   < cpp | error

   C++
   Compiler support
   Freestanding and hosted
   Language
   Standard library
   Standard library headers
   Named requirements
   Feature test macros (C++20)
   Language support library
   Concepts library (C++20)
   Metaprogramming library (C++11)
   Diagnostics library
   General utilities library
   Strings library
   Containers library
   Iterators library
   Ranges library (C++20)
   Algorithms library
   Numerics library
   Localizations library
   Input/output library
   Filesystem library (C++17)
   Regular expressions library (C++11)
   Concurrency support library (C++11)
   Technical specifications
   Symbols index
   External libraries

   Diagnostics library
   Exception handling
   exception
   uncaught_exceptionuncaught_exceptions
   (until C++20*)(C++17)
   exception_ptr
   (C++11)
   make_exception_ptr
   (C++11)
   current_exception
   (C++11)
   rethrow_exception
   (C++11)
   nested_exception
   (C++11)
   throw_with_nested
   (C++11)
   rethrow_if_nested
   (C++11)
   Exception handling failures
   terminate
   terminate_handler
   get_terminate
   (C++11)
   set_terminate
   bad_exception
   unexpected
   (until C++17*)
   unexpected_handler
   (until C++17*)
   get_unexpected
   (C++11)(until C++17*)
   set_unexpected
   (until C++17*)
   Error codes
   Error codes
   errno
   Exception categories
   logic_error
   invalid_argument
   domain_error
   length_error
   out_of_range
   runtime_error
   range_error
   overflow_error
   underflow_error
   tx_exception
   (TM TS)
   System error support
   error_category
   (C++11)
   generic_category
   (C++11)
   system_category
   (C++11)
   error_condition
   (C++11)
   errc
   (C++11)
   error_code
   (C++11)
   system_error
   (C++11)
   Assertions
   assert
   Stacktrace
   stacktrace_entry
   (C++23)
   basic_stacktrace
   (C++23)

   Defined in header <exception>
   template< class T >
   [[noreturn]] void throw_with_nested( T&& t );
                                (since C++11)

   If std::decay<T>::type is a non-final non-union class type that is
   neither std::nested_exception nor derived from std::nested_exception,
   throws an exception of an unspecified type that is publicly derived
   from both std::nested_exception and from std::decay<T>::type, and
   constructed from std::forward<T>(t). The default constructor of the
   nested_exception base class calls std::current_exception, capturing the
   currently handled exception object, if any, in a std::exception_ptr.

   Otherwise, throws std::forward<T>(t).

   Requires that std::decay<T>::type is CopyConstructible.

Parameters

   t - the exception object to throw

Return value

   (none)

Example

   Demonstrates construction and recursion through a nested exception
   object.
   Run this code
#include <exception>
#include <fstream>
#include <iostream>
#include <stdexcept>
#include <string>

// prints the explanatory string of an exception. If the exception is nested,
// recurses to print the explanatory of the exception it holds
void print_exception(const std::exception& e, int level =  0)
{
    std::cerr << std::string(level, ' ') << "exception: " << e.what() << '\n';
    try
    {
        std::rethrow_if_nested(e);
    }
    catch (const std::exception& nestedException)
    {
        print_exception(nestedException, level + 1);
    }
    catch (...) {}
}

// sample function that catches an exception and wraps it in a nested exception
void open_file(const std::string& s)
{
    try
    {
        std::ifstream file(s);
        file.exceptions(std::ios_base::failbit);
    }
    catch (...)
    {
        std::throw_with_nested(std::runtime_error("Couldn't open " + s));
    }
}

// sample function that catches an exception and wraps it in a nested exception
void run()
{
    try
    {
        open_file("nonexistent.file");
    }
    catch (...)
    {
        std::throw_with_nested(std::runtime_error("run() failed"));
    }
}

// runs the sample function above and prints the caught exception
int main()
{
    try
    {
        run();
    }
    catch (const std::exception& e)
    {
        print_exception(e);
    }
}

   Possible output:
exception: run() failed
 exception: Couldn't open nonexistent.file
  exception: basic_ios::clear

See also

   nested_exception
   (C++11)
   a mixin type to capture and store current exceptions
   (class)
   rethrow_if_nested
   (C++11)
   throws the exception from a std::nested_exception
   (function template)
   Retrieved from
   "https://en.cppreference.com/mwiki/index.php?title=cpp/error/throw_with
   _nested&oldid=157700"

Navigation

     * Online version
     * Offline version retrieved 2024-06-10 08:17.

     * This page was last modified on 1 September 2023, at 10:27.
     * This page has been accessed 74,224 times.
